Workbook

Sheet Products
A1: Product_ID | B1: Product_Name | C1: Category | D1: Subcategory | E1: Brand | F1: Cost_Price | G1: Selling_Price | H1: Supplier_ID | I1: Season | J1: Status | K1: Status2
A2: PRD001 | B2: Local Bakers Buns 1kg | C2: Bakery | D2: Buns | E2: Local Bakers | F2: 184.74 | G2: 299.73 | H2: SUP059 | I2: Summer | J2: =_xlfn.XLOOKUP(TRIM(Table1[[#This Row],[Status2]]),Data_profiling!$A$9:$A$14,Data_profiling!$B$9:$B$14,"Checkmanually") -> Active | K2: Active
A3: PRD002 | B3: Britannia Buns Pack | C3: Bakery | D3: Buns | E3: Britannia | F3: 254.05 | G3: 440.5 | H3: SUP062 | I3: Monsoon | J3: =_xlfn.XLOOKUP(TRIM(Table1[[#This Row],[Status2]]),Data_profiling!$A$9:$A$14,Data_profiling!$B$9:$B$14,"Checkmanually") -> Active | K3: Active
A4: PRD003 | B4: Harvest Gold Buns Combo | C4: Bakery | D4: Buns | E4: Harvest Gold | F4: 343.65 | G4: 589.75 | H4: SUP012 | I4: Winter | J4: =_xlfn.XLOOKUP(TRIM(Table1[[#This Row],[Status2]]),Data_profiling!$A$9:$A$14,Data_profiling!$B$9:$B$14,"Checkmanually") -> Active | K4: Active
A5: PRD004 | B5: Britannia Buns 2kg | C5: Bakery | D5: Buns | E5: Britannia | F5: 236.54 | G5: 398.25 | H5: SUP044 | I5: All Season | J5: =_xlfn.XLOOKUP(TRIM(Table1[[#This Row],[Status2]]),Data_profiling!$A$9:$A$14,Data_profiling!$B$9:$B$14,"Checkmanually") -> Active | K5: Active
A6: PRD005 | B6: Amul Paneer 250ml | C6: Bakery | D6: Buns | E6: Harvest Gold | F6: 205.27 | G6: 332.74 | H6: SUP034 | I6: Winter | J6: =_xlfn.XLOOKUP(TRIM(Table1[[#This Row],[Status2]]),Data_profiling!$A$9:$A$14,Data_profiling!$B$9:$B$14,"Checkmanually") -> Active | K6: Active
A7: PRD006 | B7: Harvest Gold Cookies 500g | C7: Bakery | D7: Cookies | E7: Harvest Gold | F7: 216.32 | G7: 343.56 | H7: SUP031 | I7: Monsoon | J7: =_xlfn.XLOOKUP(TRIM(Table1[[#This Row],[Status2]]),Data_profiling!$A$9:$A$14,Data_profiling!$B$9:$B$14,"Checkmanually") -> Active | K7: actiive
A8: PRD007 | B8: Britannia Buns 2kg v2 | C8: Bakery | D8: Buns | E8: Britannia | F8: 265.44 | G8: 437.49 | H8: SUP003 | I8: All Season | J8: =_xlfn.XLOOKUP(TRIM(Table1[[#This Row],[Status2]]),Data_profiling!$A$9:$A$14,Data_profiling!$B$9:$B$14,"Checkmanually") -> Active | K8: Active
A9: PRD008 | B9: Britannia Cookies 200g | C9: Bakery | D9: Cookies | E9: Britannia | F9: 282.88 | G9: 455.79 | H9: SUP075 | I9: Winter | J9: =_xlfn.XLOOKUP(TRIM(Table1[[#This Row],[Status2]]),Data_profiling!$A$9:$A$14,Data_profiling!$B$9:$B$14,"Checkmanually") -> Active | K9: Active
A10: PRD009 | B10: Harvest Gold Buns 200g | C10: Bakery | D10: Buns | E10: Harvest Gold | F10: 398.72 | G10: 661.91 | H10: SUP046 | I10: Monsoon | J10: =_xlfn.XLOOKUP(TRIM(Table1[[#This Row],[Status2]]),Data_profiling!$A$9:$A$14,Data_profiling!$B$9:$B$14,"Checkmanually") -> Active | K10: Active
A11: PRD010 | B11: Harvest Gold Cookies Pack | C11: Bakery | D11: Cookies | E11: Harvest Gold | F11: 107.6 | G11: 182.3 | H11: SUP041 | I11: All Season | J11: =_xlfn.XLOOKUP(TRIM(Table1[[#This Row],[Status2]]),Data_profiling!$A$9:$A$14,Data_profiling!$B$9:$B$14,"Checkmanually") -> Active | K11: Active
A12: PRD011 | B12: Britannia Rusk 1L | C12: Bakery | D12: Rusk | E12: Britannia | F12: 102.23 | G12: 168.36 | H12: SUP076 | I12: Festive | J12: =_xlfn.XLOOKUP(TRIM(Table1[[#This Row],[Status2]]),Data_profiling!$A$9:$A$14,Data_profiling!$B$9:$B$14,"Checkmanually") -> Active | K12: Active
A13: PRD012 | B13: Harvest Gold Rusk 1kg | C13: Bakery | D13: Rusk | E13: Harvest Gold | F13: 336.4 | G13: 541.35 | H13: SUP047 | I13: Summer | J13: =_xlfn.XLOOKUP(TRIM(Table1[[#This Row],[Status2]]),Data_profiling!$A$9:$A$14,Data_profiling!$B$9:$B$14,"Checkmanually") -> Active | K13: Active
... A23: PRD022 | B23: Aavin Milk Pack | C23: Dairy | D23: Milk | E23: Aavin | F23: 319.37 | G23: 397.22 | H23: SUP085 | I23: Summer | J23: =_xlfn.XLOOKUP(TRIM(Table1[[#This Row],[Status2]]),Data_profiling!$A$9:$A$14,Data_profiling!$B$9:$B$14,"Checkmanually") -> Active | K23: Active
A24: PRD023 | B24: Amul Butter 1L | C24: Dairy | D24: Butter | F24: 266.1 | G24: 342.27 | H24: SUP019 | I24: All Season | J24: =_xlfn.XLOOKUP(TRIM(Table1[[#This Row],[Status2]]),Data_profiling!$A$9:$A$14,Data_profiling!$B$9:$B$14,"Checkmanually") -> Active | K24: Active
A25: PRD024 | B25: Aavin Milk Pack v2 | C25: Dairy | D25: Milk | E25: Aavin | F25: 246.12 | G25: 313.47 | H25: SUP037 | I25: Monsoon | J25: =_xlfn.XLOOKUP(TRIM(Table1[[#This Row],[Status2]]),Data_profiling!$A$9:$A$14,Data_profiling!$B$9:$B$14,"Checkmanually") -> Active | K25: Active
A26: PRD025 | B26: Nescafe Soft Drinks Pack | C26: Beverages | D26: Soft Drinks | E26: Nescafe | F26: 285.9 | G26: 383.51 | H26: SUP065 | I26: Festive | J26: =_xlfn.XLOOKUP(TRIM(Table1[[#This Row],[Status2]]),Data_profiling!$A$9:$A$14,Data_profiling!$B$9:$B$14,"Checkmanually") -> Active | K26: Active
A27: PRD026 | B27: Nescafe Coffee 1kg | C27: Beverages | D27: Coffee | E27: Nescafe | F27: 247.25 | G27: 329.69 | H27: SUP042 | I27: Festive | J27: =_xlfn.XLOOKUP(TRIM(Table1[[#This Row],[Status2]]),Data_profiling!$A$9:$A$14,Data_profiling!$B$9:$B$14,"Checkmanually") -> Active | K27: Active
A28: PRD027 | B28: Coca-Cola Tea 1kg | C28: Beverages | D28: Tea | E28: Coca-Cola | F28: 106.99 | G28: 139.21 | H28: SUP074 | I28: Festive | J28: =_xlfn.XLOOKUP(TRIM(Table1[[#This Row],[Status2]]),Data_profiling!$A$9:$A$14,Data_profiling!$B$9:$B$14,"Checkmanually") -> Active | K28: Active
A29: PRD028 | B29: Tata Tea Soft Drinks 500g | C29: Beverages | D29: Soft Drinks | E29: Tata Tea | F29: 309.98 | G29: 380.12 | H29: SUP067 | I29: Monsoon | J29: =_xlfn.XLOOKUP(TRIM(Table1[[#This Row],[Status2]]),Data_profiling!$A$9:$A$14,Data_profiling!$B$9:$B$14,"Checkmanually") -> Active | K29: Active
A30: PRD029 | B30: Pepsi Tea 200g | C30: Beverages | D30: Tea | E30: Pepsi | F30: 261.22 | G30: 332.73 | H30: SUP012 | I30: Monsoon | J30: =_xlfn.XLOOKUP(TRIM(Table1[[#This Row],[Status2]]),Data_profiling!$A$9:$A$14,Data_profiling!$B$9:$B$14,"Checkmanually") -> Active | K30: Active
A31: PRD030 | B31: Nescafe Tea Combo | C31: Beverages | D31: Tea | E31: Nescafe | F31: 142 | G31: 172.63 | H31: SUP021 | I31: Winter | J31: =_xlfn.XLOOKUP(TRIM(Table1[[#This Row],[Status2]]),Data_profiling!$A$9:$A$14,Data_profiling!$B$9:$B$14,"Checkmanually") -> Active | K31: Active
A32: PRD031 | B32: Nescafe Coffee Pack | C32: Beverages | D32: Coffee | E32: Nescafe | F32: 271.78 | G32: 342.46 | H32: SUP071 | I32: All Season | J32: =_xlfn.XLOOKUP(TRIM(Table1[[#This Row],[Status2]]),Data_profiling!$A$9:$A$14,Data_profiling!$B$9:$B$14,"Checkmanually") -> Active | K32: Active
A33: PRD032 | B33: Coca-Cola Coffee Combo | C33: Beverages | D33: Coffee | E33: Coca-Cola | F33: 115.91 | G33: 141.11 | H33: SUP052 | I33: Festive | J33: =_xlfn.XLOOKUP(TRIM(Table1[[#This Row],[Status2]]),Data_profiling!$A$9:$A$14,Data_profiling!$B$9:$B$14,"Checkmanually") -> Active | K33: Active
A34: PRD033 | B34: Bisleri Soft Drinks 2kg | C34: Beverages | D34: Soft Drinks | E34: Bisleri | F34: 177.03 | G34: 217.42 | H34: SUP047 | I34: Festive | J34: =_xlfn.XLOOKUP(TRIM(Table1[[#This Row],[Status2]]),Data_profiling!$A$9:$A$14,Data_profiling!$B$9:$B$14,"Checkmanually") -> Active | K34: Active
A35: PRD034 | B35: Nescafe Coffee 500g | C35: Beverages | D35: Coffee | E35: Nescafe | F35: 97.35 | G35: 124.84 | H35: SUP037 | I35: Monsoon | J35: =_xlfn.XLOOKUP(TRIM(Table1[[#This Row],[Status2]]),Data_profiling!$A$9:$A$14,Data_profiling!$B$9:$B$14,"Checkmanually") -> Active | K35: Active
A36: PRD035 | B36: Coca-Cola Coffee 500g | C36: Beverages | D36: Coffee | E36: Coca-Cola | F36: 389.8 | G36: 503.36 | H36: SUP031 | I36: Summer | J36: =_xlfn.XLOOKUP(TRIM(Table1[[#This Row],[Status2]]),Data_profiling!$A$9:$A$14,Data_profiling!$B$9:$B$14,"Checkmanually") -> Active | K36: Active
... A48: PRD047 | B48: Lays Chocolates Combo | C48: Snacks | D48: Chocolates | E48: Lays | F48: 343.89 | G48: 474.19 | H48: SUP049 | I48: Winter | J48: =_xlfn.XLOOKUP(TRIM(Table1[[#This Row],[Status2]]),Data_profiling!$A$9:$A$14,Data_profiling!$B$9:$B$14,"Checkmanually") -> Active | K48: Active
A49: PRD048 | B49: Lays Chocolates 1kg | C49: Snacks | D49: Chocolates | E49: Lays | F49: 109.21 | G49: 147.72 | H49: SUP037 | J49: =_xlfn.XLOOKUP(TRIM(Table1[[#This Row],[Status2]]),Data_profiling!$A$9:$A$14,Data_profiling!$B$9:$B$14,"Checkmanually") -> Active | K49: Active
A50: PRD049 | B50: Cadbury Chips 1kg | C50: Snacks | D50: Chips | E50: Cadbury | F50: 308.94 | G50: 418.79 | H50: SUP013 | I50: Monsoon | J50: =_xlfn.XLOOKUP(TRIM(Table1[[#This Row],[Status2]]),Data_profiling!$A$9:$A$14,Data_profiling!$B$9:$B$14,"Checkmanually") -> Active | K50: Active
A51: PRD050 | B51: Parle Namkeen 500g | C51: Snacks | D51: Namkeen | E51: Parle | F51: 37.48 | G51: 51.33 | H51: SUP038 | I51: Winter | J51: =_xlfn.XLOOKUP(TRIM(Table1[[#This Row],[Status2]]),Data_profiling!$A$9:$A$14,Data_profiling!$B$9:$B$14,"Checkmanually") -> Active | K51: Active
A52: PRD051 | B52: Cadbury Biscuits 250ml | C52: Snacks | D52: Biscuits | E52: Cadbury | F52: 112.8 | G52: 147.97 | H52: SUP024 | I52: Summer | J52: =_xlfn.XLOOKUP(TRIM(Table1[[#This Row],[Status2]]),Data_profiling!$A$9:$A$14,Data_profiling!$B$9:$B$14,"Checkmanually") -> Active | K52: Active
A53: PRD052 | B53: Lays Namkeen 200g | C53: Snacks | D53: Namkeen | E53: Lays | F53: 255.49 | G53: 328.59 | H53: SUP075 | I53: Summer | J53: =_xlfn.XLOOKUP(TRIM(Table1[[#This Row],[Status2]]),Data_profiling!$A$9:$A$14,Data_profiling!$B$9:$B$14,"Checkmanually") -> Active | K53: Active
A54: PRD053 | B54: Cadbury Namkeen Pack | C54: Snacks | D54: Namkeen | E54: Cadbury | F54: 194.64 | G54: 262.77 | H54: SUP060 | I54: Winter | J54: =_xlfn.XLOOKUP(TRIM(Table1[[#This Row],[Status2]]),Data_profiling!$A$9:$A$14,Data_profiling!$B$9:$B$14,"Checkmanually") -> Active | K54: Active
A55: PRD054 | B55: Lays Namkeen 2kg | C55: Snacks | D55: Namkeen | E55: Lays | F55: 379.19 | G55: 530.16 | H55: SUP039 | I55: Monsoon | J55: =_xlfn.XLOOKUP(TRIM(Table1[[#This Row],[Status2]]),Data_profiling!$A$9:$A$14,Data_profiling!$B$9:$B$14,"Checkmanually") -> Active | K55: Active
A56: PRD055 | B56: Cadbury Biscuits Pack | C56: Snacks | D56: Biscuits | E56: Cadbury | F56: 95.7 | G56: 125.15 | H56: SUP062 | I56: All Season | J56: =_xlfn.XLOOKUP(TRIM(Table1[[#This Row],[Status2]]),Data_profiling!$A$9:$A$14,Data_profiling!$B$9:$B$14,"Checkmanually") -> Active | K56: Active
A57: PRD056 | B57: Cadbury Namkeen Combo | C57: Snacks | D57: Namkeen | E57: Cadbury | F57: 238.43 | G57: 333.54 | H57: SUP038 | I57: All Season | J57: =_xlfn.XLOOKUP(TRIM(Table1[[#This Row],[Status2]]),Data_profiling!$A$9:$A$14,Data_profiling!$B$9:$B$14,"Checkmanually") -> Active | K57: Active
A58: PRD057 | B58: Parle Chocolates 500g | C58: Snacks | D58: Chocolates | E58: Parle | F58: 235.05 | G58: 317.99 | H58: SUP007 | I58: Festive | J58: =_xlfn.XLOOKUP(TRIM(Table1[[#This Row],[Status2]]),Data_profiling!$A$9:$A$14,Data_profiling!$B$9:$B$14,"Checkmanually") -> Active | K58: Active
A59: PRD058 | B59: Himalaya Skin Care 1L | C59: Personal Care | D59: Skin Care | E59: Himalaya | F59: 250.68 | G59: 339.13 | H59: SUP082 | I59: Summer | J59: =_xlfn.XLOOKUP(TRIM(Table1[[#This Row],[Status2]]),Data_profiling!$A$9:$A$14,Data_profiling!$B$9:$B$14,"Checkmanually") -> Active | K59: Active
A60: PRD059 | B60: Colgate Toothpaste 1kg | C60: Personal Care | D60: Toothpaste | E60: Colgate | F60: 363.29 | G60: 507.5 | H60: SUP040 | I60: Monsoon | J60: =_xlfn.XLOOKUP(TRIM(Table1[[#This Row],[Status2]]),Data_profiling!$A$9:$A$14,Data_profiling!$B$9:$B$14,"Checkmanually") -> Active | K60: Active
...

Sheet Data_profiling
A1: Column_name | B1: Issue_Description | C1: Columns_affected | D1: Changes_done
A2: Brand | B2: Blanks | C2: 5 | D2: Highlighted
A3: Season | B3: Blanks | C3: 5 | D3: Highlighted
A4: Status | B4: Different Formats | D4: Fixed using Mapping
A9: actiive | B9: Active
A10: Active | B10: Active
A11: Actve | B11: Active
A12: Inactive | B12: Inactive
A13: Inactve | B13: Inactive
A14: In-active | B14: Inactive
