Workbook

Sheet Sheet1
A1: Customer_ID | B1: Customer_Name | C1: Gender | D1: DOB | E1: Phone | F1: Email | G1: City | H1: State | I1: Region | J1: Membership | K1: Column1 | L1: Registration_Date
A2: CUST0001 | B2: Revathi Balan | C2: Female | D2: 31272 | E2: 9204528821 | F2: revathi1@gmail.com | G2: Coimbatore | H2: Tamil Nadu | I2: South | J2: Bronze | K2: =_xlfn.XLOOKUP(TRIM(Table1[[#This Row],[Membership]]),Sheet2!$A$2:$A$7,Sheet2!$B$2:$B$7,"Checkmanually") -> Bronze | L2: 44659
A3: CUST0002 | B3: Eswari Murugan | C3: Female | D3: 21939 | E3: 9362238769 | F3: eswari2@gmail.com | G3: Tiruppur | H3: Tamil Nadu | I3: South | J3: Silver | K3: =_xlfn.XLOOKUP(TRIM(Table1[[#This Row],[Membership]]),Sheet2!$A$2:$A$7,Sheet2!$B$2:$B$7,"Checkmanually") -> Silver | L3: 45809
A4: CUST0003 | B4: Banu Balan | C4: Female | D4: 22236 | E4: 9222912620 | F4: banu3@gmail.com | G4: Erode | H4: Tamil Nadu | I4: South | J4: Bronze | K4: =_xlfn.XLOOKUP(TRIM(Table1[[#This Row],[Membership]]),Sheet2!$A$2:$A$7,Sheet2!$B$2:$B$7,"Checkmanually") -> Bronze | L4: 44349
A5: CUST0004 | B5: Naveen Sharma | C5: Male | D5: 21314 | E5: 9806272779 | F5: naveen4@gmail.com | G5: Coimbatore | H5: Tamil Nadu | I5: South | J5: Silver | K5: =_xlfn.XLOOKUP(TRIM(Table1[[#This Row],[Membership]]),Sheet2!$A$2:$A$7,Sheet2!$B$2:$B$7,"Checkmanually") -> Silver | L5: 44988
A6: CUST0005 | B6: Pandi Raj | C6: Male | D6: 35481 | E6: 9123876200 | F6: pandi5@gmail.com | G6: Guwahati | H6: Assam | I6: East | J6: Silver | K6: =_xlfn.XLOOKUP(TRIM(Table1[[#This Row],[Membership]]),Sheet2!$A$2:$A$7,Sheet2!$B$2:$B$7,"Checkmanually") -> Silver | L6: 45509
A7: CUST0006 | B7: Thiru Devi | C7: Male | D7: 38850 | E7: 9967934041 | F7: thiru6@gmail.com | G7: Kanpur | H7: Uttar Pradesh | I7: North | J7: Silver | K7: =_xlfn.XLOOKUP(TRIM(Table1[[#This Row],[Membership]]),Sheet2!$A$2:$A$7,Sheet2!$B$2:$B$7,"Checkmanually") -> Silver | L7: 43501
A8: CUST0007 | B8: Senthil Pillai | C8: Male | D8: 36564 | E8: 9464577685 | F8: senthil7@gmail.com | G8: Salem | H8: Tamil Nadu | I8: South | J8: Silver | K8: =_xlfn.XLOOKUP(TRIM(Table1[[#This Row],[Membership]]),Sheet2!$A$2:$A$7,Sheet2!$B$2:$B$7,"Checkmanually") -> Silver | L8: 45834
A9: CUST0008 | B9: Eswari Raj | C9: Female | D9: 34376 | E9: 9633597839 | F9: eswari8@gmail.com | G9: Erode | H9: Tamil Nadu | I9: South | J9: Silver | K9: =_xlfn.XLOOKUP(TRIM(Table1[[#This Row],[Membership]]),Sheet2!$A$2:$A$7,Sheet2!$B$2:$B$7,"Checkmanually") -> Silver | L9: 43927
A10: CUST0009 | B10: Mani Nair | C10: Male | D10: 37648 | E10: 9408545686 | F10: mani9@gmail.com | G10: Chennai | H10: Tamil Nadu | I10: South | J10: Bronze | K10: =_xlfn.XLOOKUP(TRIM(Table1[[#This Row],[Membership]]),Sheet2!$A$2:$A$7,Sheet2!$B$2:$B$7,"Checkmanually") -> Bronze | L10: 43977
A11: CUST0010 | B11: Tara Achari | C11: Female | D11: 33263 | E11: 9770629385 | F11: tara10@gmail.com | G11: Erode | H11: Tamil Nadu | I11: South | J11: Bronze | K11: =_xlfn.XLOOKUP(TRIM(Table1[[#This Row],[Membership]]),Sheet2!$A$2:$A$7,Sheet2!$B$2:$B$7,"Checkmanually") -> Bronze | L11: 44026
A12: CUST0011 | B12: Prasath Mudaliar | C12: Male | D12: 39036 | E12: 9735509839 | F12: prasath11@gmail.com | G12: Chennai | H12: Tamil Nadu | I12: South | J12: Bronze | K12: =_xlfn.XLOOKUP(TRIM(Table1[[#This Row],[Membership]]),Sheet2!$A$2:$A$7,Sheet2!$B$2:$B$7,"Checkmanually") -> Bronze | L12: 43489
A13: CUST0012 | B13: Meena Gupta | C13: Female | D13: 37491 | E13: 9558601461 | F13: meena12@gmail.com | G13: Chennai | H13: Tamil Nadu | I13: South | J13: Bronze | K13: =_xlfn.XLOOKUP(TRIM(Table1[[#This Row],[Membership]]),Sheet2!$A$2:$A$7,Sheet2!$B$2:$B$7,"Checkmanually") -> Bronze | L13: 45047
... A293: CUST0292 | B293: Nirmala Venkataraman | C293: Female | D293: 25491 | E293: 9322664095 | F293: nirmala292@gmail.com | G293: Tiruppur | H293: Tamil Nadu | I293: South | J293: Silver | K293: =_xlfn.XLOOKUP(TRIM(Table1[[#This Row],[Membership]]),Sheet2!$A$2:$A$7,Sheet2!$B$2:$B$7,"Checkmanually") -> Silver | L293: 44136
A294: CUST0293 | B294: Suresh Chandran | C294: Male | D294: 35225 | E294: 9468999657 | F294: suresh293@gmail.com | G294: Mysuru | H294: Karnataka | J294: Gold | K294: =_xlfn.XLOOKUP(TRIM(Table1[[#This Row],[Membership]]),Sheet2!$A$2:$A$7,Sheet2!$B$2:$B$7,"Checkmanually") -> Gold | L294: 44662
A295: CUST0294 | B295: Deepak Venkataraman | C295: Male | D295: 20441 | E295: 9223139628 | F295: deepak294@gmail.com | G295: Salem | H295: Tamil Nadu | I295: South | J295: Silver | K295: =_xlfn.XLOOKUP(TRIM(Table1[[#This Row],[Membership]]),Sheet2!$A$2:$A$7,Sheet2!$B$2:$B$7,"Checkmanually") -> Silver | L295: 44127
A296: CUST0295 | B296: Latha Gounder | C296: Female | D296: 35302 | E296: 9595378308 | F296: latha295@gmail.com | G296: Madurai | H296: Tamil Nadu | I296: South | J296: Silver | K296: =_xlfn.XLOOKUP(TRIM(Table1[[#This Row],[Membership]]),Sheet2!$A$2:$A$7,Sheet2!$B$2:$B$7,"Checkmanually") -> Silver | L296: 45086
A297: CUST0296 | B297: Uma Pandian | C297: Female | D297: 34433 | E297: 9605504475 | F297: uma296@gmail.com | G297: Kochi | H297: Kerala | I297: South | J297: Bronze | K297: =_xlfn.XLOOKUP(TRIM(Table1[[#This Row],[Membership]]),Sheet2!$A$2:$A$7,Sheet2!$B$2:$B$7,"Checkmanually") -> Bronze | L297: 43675
A298: CUST0297 | B298: Nithya Sharma | C298: Female | D298: 20681 | E298: 9207927292 | F298: nithya297@gmail.com | G298: Madurai | H298: Tamil Nadu | I298: South | J298: Gold | K298: =_xlfn.XLOOKUP(TRIM(Table1[[#This Row],[Membership]]),Sheet2!$A$2:$A$7,Sheet2!$B$2:$B$7,"Checkmanually") -> Gold | L298: 45587
A299: CUST0298 | B299: Divya Naicker | C299: Female | D299: 32897 | E299: 9183306581 | F299: divya298@gmail.com | G299: Chennai | H299: Tamil Nadu | I299: South | J299: Silver | K299: =_xlfn.XLOOKUP(TRIM(Table1[[#This Row],[Membership]]),Sheet2!$A$2:$A$7,Sheet2!$B$2:$B$7,"Checkmanually") -> Silver | L299: 43790
A300: CUST0299 | B300: Chandran Krishnan | C300: Male | D300: 25119 | E300: 9484492979 | F300: chandran299@gmail.com | G300: Coimbatore | H300: Tamil Nadu | I300: South | J300: Bronze | K300: =_xlfn.XLOOKUP(TRIM(Table1[[#This Row],[Membership]]),Sheet2!$A$2:$A$7,Sheet2!$B$2:$B$7,"Checkmanually") -> Bronze | L300: 44905
A301: CUST0300 | B301: Indira Prabhu | C301: Female | D301: 37532 | E301: 9574656314 | F301: indira300@gmail.com | G301: Coimbatore | H301: Tamil Nadu | I301: South | J301: Bronze | K301: =_xlfn.XLOOKUP(TRIM(Table1[[#This Row],[Membership]]),Sheet2!$A$2:$A$7,Sheet2!$B$2:$B$7,"Checkmanually") -> Bronze | L301: 43986
A302: CUST0301 | B302: Dinesh Chandran | C302: Male | D302: 23458 | E302: 9841254136 | F302: dinesh301@gmail.com | G302: Kochi | H302: Kerala | I302: South | J302: Bronze | K302: =_xlfn.XLOOKUP(TRIM(Table1[[#This Row],[Membership]]),Sheet2!$A$2:$A$7,Sheet2!$B$2:$B$7,"Checkmanually") -> Bronze | L302: 44700
A303: CUST0302 | B303: Rajesh Reddy | C303: Male | D303: 21684 | E303: 9923682643 | F303: rajesh302@gmail.com | G303: Coimbatore | H303: Tamil Nadu | I303: South | J303: Bronze | K303: =_xlfn.XLOOKUP(TRIM(Table1[[#This Row],[Membership]]),Sheet2!$A$2:$A$7,Sheet2!$B$2:$B$7,"Checkmanually") -> Bronze | L303: 44646
A304: CUST0303 | B304: Kamala Subramaniam | C304: Female | D304: 27906 | E304: 9198125433 | F304: kamala303@gmail.com | G304: Salem | H304: Tamil Nadu | I304: South | J304: Silver | K304: =_xlfn.XLOOKUP(TRIM(Table1[[#This Row],[Membership]]),Sheet2!$A$2:$A$7,Sheet2!$B$2:$B$7,"Checkmanually") -> Silver | L304: 43920
A305: CUST0304 | B305: Unknown | C305: Female | D305: 31136 | E305: 9830100976 | F305: yamuna304@gmail.com | G305: Coimbatore | H305: Tamil Nadu | I305: South | J305: Bronze | K305: =_xlfn.XLOOKUP(TRIM(Table1[[#This Row],[Membership]]),Sheet2!$A$2:$A$7,Sheet2!$B$2:$B$7,"Checkmanually") -> Bronze | L305: 43888
A306: CUST0305 | B306: Hemalatha Mudaliar | C306: Female | D306: 23255 | E306: 9280262874 | F306: hemalatha305@gmail.com | G306: Salem | H306: Tamil Nadu | I306: South | J306: Bronze | K306: =_xlfn.XLOOKUP(TRIM(Table1[[#This Row],[Membership]]),Sheet2!$A$2:$A$7,Sheet2!$B$2:$B$7,"Checkmanually") -> Bronze | L306: 45821
... A446: CUST0445 | B446: Anjali Kumar | C446: Female | D446: 20380 | E446: 9562572075 | F446: anjali445@gmail.com | G446: Madurai | H446: Tamil Nadu | I446: South | J446: Silver | K446: =_xlfn.XLOOKUP(TRIM(Table1[[#This Row],[Membership]]),Sheet2!$A$2:$A$7,Sheet2!$B$2:$B$7,"Checkmanually") -> Silver | L446: 43516
A447: CUST0446 | B447: Ramesh Sharma | C447: Male | D447: 25126 | E447: 9232975024 | F447: ramesh446@gmail.com | G447: Chennai | H447: Tamil Nadu | J447: Silver | K447: =_xlfn.XLOOKUP(TRIM(Table1[[#This Row],[Membership]]),Sheet2!$A$2:$A$7,Sheet2!$B$2:$B$7,"Checkmanually") -> Silver | L447: 44783
A448: CUST0447 | B448: Harini Krishnan | C448: Female | D448: 28286 | E448: 9605408862 | F448: harini447@gmail.com | G448: Pune | H448: Maharashtra | I448: West | J448: Bronze | K448: =_xlfn.XLOOKUP(TRIM(Table1[[#This Row],[Membership]]),Sheet2!$A$2:$A$7,Sheet2!$B$2:$B$7,"Checkmanually") -> Bronze | L448: 44027
A449: CUST0448 | B449: Sanjay Achari | C449: Male | D449: 26059 | E449: 9971388578 | F449: sanjay448@gmail.com | G449: Erode | H449: Tamil Nadu | I449: South | J449: Silver | K449: =_xlfn.XLOOKUP(TRIM(Table1[[#This Row],[Membership]]),Sheet2!$A$2:$A$7,Sheet2!$B$2:$B$7,"Checkmanually") -> Silver | L449: 45298
A450: CUST0449 | B450: Sudha Sekar | C450: Female | D450: 34486 | E450: 9250188999 | F450: sudha449@gmail.com | G450: Mysuru | H450: Karnataka | I450: South | J450: Bronze | K450: =_xlfn.XLOOKUP(TRIM(Table1[[#This Row],[Membership]]),Sheet2!$A$2:$A$7,Sheet2!$B$2:$B$7,"Checkmanually") -> Bronze | L450: 43763
A451: CUST0450 | B451: Bhavani Chettiar | C451: Female | D451: 26593 | E451: 9303546093 | F451: bhavani450@gmail.com | G451: Bengaluru | H451: Karnataka | I451: South | J451: Gold | K451: =_xlfn.XLOOKUP(TRIM(Table1[[#This Row],[Membership]]),Sheet2!$A$2:$A$7,Sheet2!$B$2:$B$7,"Checkmanually") -> Gold | L451: 43554
A452: CUST0451 | B452: Divya Nair | C452: Female | D452: 30943 | E452: 9272134233 | F452: divya451@gmail.com | G452: Madurai | H452: Tamil Nadu | I452: South | J452: Silver | K452: =_xlfn.XLOOKUP(TRIM(Table1[[#This Row],[Membership]]),Sheet2!$A$2:$A$7,Sheet2!$B$2:$B$7,"Checkmanually") -> Silver | L452: 43230
A453: CUST0452 | B453: Dhanya Varma | C453: Female | D453: 28799 | E453: 9552147658 | F453: dhanya452@gmail.com | G453: Mysuru | H453: Karnataka | I453: South | J453: Bronze | K453: =_xlfn.XLOOKUP(TRIM(Table1[[#This Row],[Membership]]),Sheet2!$A$2:$A$7,Sheet2!$B$2:$B$7,"Checkmanually") -> Bronze | L453: 43587
A454: CUST0453 | B454: Prasath Nair | C454: Male | D454: 24265 | E454: 9906476640 | F454: prasath453@gmail.com | G454: Mysuru | H454: Karnataka | I454: South | J454: Bronze | K454: =_xlfn.XLOOKUP(TRIM(Table1[[#This Row],[Membership]]),Sheet2!$A$2:$A$7,Sheet2!$B$2:$B$7,"Checkmanually") -> Bronze | L454: 44431
A455: CUST0454 | B455: Raghav Nair | C455: Male | D455: 32831 | E455: 9217824679 | F455: raghav454@gmail.com | G455: Bengaluru | H455: Karnataka | I455: South | J455: Silver | K455: =_xlfn.XLOOKUP(TRIM(Table1[[#This Row],[Membership]]),Sheet2!$A$2:$A$7,Sheet2!$B$2:$B$7,"Checkmanually") -> Silver | L455: 43639
A456: CUST0455 | B456: Nithya Venkataraman | C456: Female | D456: 36474 | E456: 9923973312 | F456: nithya455@gmail.com | G456: Pune | H456: Maharashtra | I456: West | J456: Gold | K456: =_xlfn.XLOOKUP(TRIM(Table1[[#This Row],[Membership]]),Sheet2!$A$2:$A$7,Sheet2!$B$2:$B$7,"Checkmanually") -> Gold | L456: 43156
A457: CUST0456 | B457: Kamala Devi | C457: Female | D457: 31301 | E457: 9741117091 | F457: kamala456@gmail.com | G457: Coimbatore | H457: Tamil Nadu | I457: South | J457: Bronze | K457: =_xlfn.XLOOKUP(TRIM(Table1[[#This Row],[Membership]]),Sheet2!$A$2:$A$7,Sheet2!$B$2:$B$7,"Checkmanually") -> Bronze | L457: 44860
A458: CUST0457 | B458: Nithya Raj | C458: Female | D458: 29337 | E458: 9188707067 | F458: nithya457@gmail.com | G458: Bengaluru | H458: Karnataka | I458: South | J458: Silver | K458: =_xlfn.XLOOKUP(TRIM(Table1[[#This Row],[Membership]]),Sheet2!$A$2:$A$7,Sheet2!$B$2:$B$7,"Checkmanually") -> Silver | L458: 45091
...

Sheet Sheet2
A1: Raw_value | B1: Mapping_value
A2: Bronz | B2: Bronze
A3: Gld | B3: Gold
A4: Silvr | B4: Silver
A5: Silver | B5: Silver
A6: Gold | B6: Gold
A7: Bronze | B7: Bronze
